Workbook

Sheet Umumiy
A1: Frazeologik va ko'chma ma'noli birliklar qatnashgan izohlar
A2: Manba: GitHub'dagi ochiq datasetlar (Google Play ilova sharhlari, UzABSA restoran sharhlari). Leksikonlar: frazeologik_lugat.csv, kochma_leksikon.csv.
A4: 1. Manbalar bo'yicha
A5: Manba | B5: Jami izoh | C5: Mos izohlar | D5: Ulushi
A6: Google Play | B6: =COUNTIF('Barcha izohlar'!$C$2:$C$5371,A6) -> 3719 | C6: =COUNTIFS('Barcha izohlar'!$C$2:$C$5371,A6,'Barcha izohlar'!$F$2:$F$5371,"ha") -> 1142 | D6: =IF(B6=0,0,C6/B6) -> 0.30707179
A7: Restoran | B7: =COUNTIF('Barcha izohlar'!$C$2:$C$5371,A7) -> 1651 | C7: =COUNTIFS('Barcha izohlar'!$C$2:$C$5371,A7,'Barcha izohlar'!$F$2:$F$5371,"ha") -> 607 | D7: =IF(B7=0,0,C7/B7) -> 0.36765597
A8: Jami | B8: =SUM(B6:B7) -> 5370 | C8: =SUM(C6:C7) -> 1749 | D8: =IF(B8=0,0,C8/B8) -> 0.32569832
A10: 2. Leksikonlar bo'yicha va tekshiruv holati
A11: Varaq | B11: Mosliklar | C11: ha | D11: yo'q | E11: Tekshirilmagan
A12: Frazeologik iboralar | B12: =COUNTA(Iboralar!$A$2:$A$433) -> 432 | C12: =COUNTIF(Iboralar!$J$2:$J$433,"ha") -> 0 | D12: =COUNTIF(Iboralar!$J$2:$J$433,"yo'q") -> 0 | E12: =COUNTBLANK(Iboralar!$J$2:$J$433) -> 432
A13: Ko'chma so'zlar | B13: =COUNTA('Ko''chma so''zlar'!$A$2:$A$1929) -> 1928 | C13: =COUNTIF('Ko''chma so''zlar'!$J$2:$J$1929,"ha") -> 0 | D13: =COUNTIF('Ko''chma so''zlar'!$J$2:$J$1929,"yo'q") -> 0 | E13: =COUNTBLANK('Ko''chma so''zlar'!$J$2:$J$1929) -> 1928
A15: 3. Eng ko'p uchragan frazeologik iboralar
A16: Ibora | B16: Soni
A17: yaxshi ko‘rmoq | B17: =COUNTIF(Iboralar!$G$2:$G$433,A17) -> 60
A18: maslahat bermoq | B18: =COUNTIF(Iboralar!$G$2:$G$433,A18) -> 35
A19: tashrif buyurmoq | B19: =COUNTIF(Iboralar!$G$2:$G$433,A19) -> 28
A20: to‘g‘ri kelgan | B20: =COUNTIF(Iboralar!$G$2:$G$433,A20) -> 16
A21: amalga oshmoq amalga oshirmoq | B21: =COUNTIF(Iboralar!$G$2:$G$433,A21) -> 15
A22: javob bermoq | B22: =COUNTIF(Iboralar!$G$2:$G$433,A22) -> 15
A23: e’tibor bermoq | B23: =COUNTIF(Iboralar!$G$2:$G$433,A23) -> 12
A24: mos kelmoq | B24: =COUNTIF(Iboralar!$G$2:$G$433,A24) -> 11
A25: ma’lumot bermoq | B25: =COUNTIF(Iboralar!$G$2:$G$433,A25) -> 10
A26: yo‘l qo‘ymoq | B26: =COUNTIF(Iboralar!$G$2:$G$433,A26) -> 8
A27: ish(i) tushdi | B27: =COUNTIF(Iboralar!$G$2:$G$433,A27) -> 8
A28: ish(i) tushdi ishga tushirmoq kim? nimani? (varianti: ishga tushmoq) | B28: =COUNTIF(Iboralar!$G$2:$G$433,A28) -> 8
... A36: buning ustiga | B36: =COUNTIF(Iboralar!$G$2:$G$433,A36) -> 4
A38: Qanday ishlatiladi
A39: • Iboralar va Ko'chma so'zlar varaqlarida sariq ustun - annotator to'ldiradi.
A40: • Tekshiruv: ro'yxatdan ha / yo'q / shubhali tanlang; qator yashil yoki qizil rangga kiradi.
A41: • Izoh matnida topilgan parcha qizil qalin harf bilan ajratilgan.
A42: • Ko'chma so'zlar ko'pincha to'g'ri ma'noda keladi - ularni ayniqsa diqqat bilan tekshiring.
A43: • Har ustun sarlavhasida filtr bor; bitta izohda bir nechta birlik bo'lsa, u bir necha qatorda keladi.

Sheet Iboralar
A1: № | B1: Izoh ID | C1: Manba | D1: Sentiment | E1: Izoh matni | F1: Topilgan parcha | G1: Leksikon birligi | H1: Lug'aviy izoh (ma'nosi) | I1: Lug'at sahifasi | J1: Tekshiruv (ha / yo'q / shubhali) | K1: Annotator izohi
A2: 1 | B2: gp_pos_4 | C2: Google Play | D2: ijobiy | E2: Ajoyib application Gap bolishi mumkinmas. Juda ham zo'r | F2: gap bolishi | G2: gap bo‘lmoq | H2: GAP | I2: 169
A3: 2 | B3: gp_pos_15 | C3: Google Play | D3: ijobiy | E3: Yashang! :-) Baraka toping! :-) | F3: baraka toping | G3: baraka top(gur) baraka topmaslik | H3: omad tilab tahsin bildirmoq. ijobiy, foydali natijaga erishmaslik. | I3: 61
A4: 3 | B4: gp_pos_19 | C4: Google Play | D4: ijobiy | E4: Taklif Agarda u halqaro qilib tuzilganda boshqa millat vakillari ham O'zbek milliy taomlariga baho berishgan bÃ¶lardi. Lekin, dastur uchun RESPECT!!! | F4: baho berishgan | G4: baho bermoq | H4: qadr-qiymatini belgilamoq, baholamoq. | I4: 56
A5: 4 | B5: gp_pos_25 | C5: Google Play | D5: ijobiy | E5: Men seni juda yaxshi ko'rgan narsamni pishirishingiz mumkin, agar bo'sh vaqtingiz bo'lsa, biron narsa tayyorlashingiz mumkin | F5: yaxshi ko'rgan | G5: yaxshi ko‘rmoq | H5: 1) kim? kimni? sevmoq, oshiq-ma’shuq bo‘lmoq (qiz bilan yigit, er bilan xotin). 2) kim? kimni? sevmoq, izzat-hurmat qilmoq (ona bolani, aka ukani). 3) kim? nimani? ba’zan nima? kimni? yoqtirmoq. | I5: 546
A6: 5 | B6: gp_pos_112 | C6: Google Play | D6: ijobiy | E6: Gap bo'lishi mumkin emas | F6: gap bo'lishi | G6: gap bo‘lmoq | H6: GAP | I6: 169
A7: 6 | B7: gp_pos_131 | C7: Google Play | D7: ijobiy | E7: Zo'r dastur. To'lovlarni amalga oshirish uchun juda qulay. Hamma narsa A + ni osonlashtirdi | F7: amalga oshirish | G7: amalga oshmoq amalga oshirmoq | H7: voqelikka aylanmoq. | I7: 39
A8: 7 | B8: gp_pos_137 | C8: Google Play | D8: ijobiy | E8: Uni hozirda ishlatgan eng yaxshi ilovani yaxshi ko'rish | F8: yaxshi ko'rish | G8: yaxshi ko‘rmoq | H8: 1) kim? kimni? sevmoq, oshiq-ma’shuq bo‘lmoq (qiz bilan yigit, er bilan xotin). 2) kim? kimni? sevmoq, izzat-hurmat qilmoq (ona bolani, aka ukani). 3) kim? nimani? ba’zan nima? kimni? yoqtirmoq. | I8: 546
A9: 8 | B9: gp_pos_147 | C9: Google Play | D9: ijobiy | E9: To'liq telefonda 3 sekundda uni yaxshi ko'rishardi | F9: yaxshi ko'rishardi | G9: yaxshi ko‘rmoq | H9: 1) kim? kimni? sevmoq, oshiq-ma’shuq bo‘lmoq (qiz bilan yigit, er bilan xotin). 2) kim? kimni? sevmoq, izzat-hurmat qilmoq (ona bolani, aka ukani). 3) kim? nimani? ba’zan nima? kimni? yoqtirmoq. | I9: 546
A10: 9 | B10: gp_pos_169 | C10: Google Play | D10: ijobiy | E10: Bu ilovani yaxshi ko'raman. Hammaga tavsiya eting | F10: yaxshi ko'raman | G10: yaxshi ko‘rmoq | H10: 1) kim? kimni? sevmoq, oshiq-ma’shuq bo‘lmoq (qiz bilan yigit, er bilan xotin). 2) kim? kimni? sevmoq, izzat-hurmat qilmoq (ona bolani, aka ukani). 3) kim? nimani? ba’zan nima? kimni? yoqtirmoq. | I10: 546
A11: 10 | B11: gp_pos_170 | C11: Google Play | D11: ijobiy | E11: Bu ilovani yaxshi ko'raman | F11: yaxshi ko'raman | G11: yaxshi ko‘rmoq | H11: 1) kim? kimni? sevmoq, oshiq-ma’shuq bo‘lmoq (qiz bilan yigit, er bilan xotin). 2) kim? kimni? sevmoq, izzat-hurmat qilmoq (ona bolani, aka ukani). 3) kim? nimani? ba’zan nima? kimni? yoqtirmoq. | I11: 546
A12: 11 | B12: gp_pos_177 | C12: Google Play | D12: ijobiy | E12: Buning ustida ishlashing kerak | F12: buning ustida | G12: buning ustiga | H12: voqe bo‘lgani yetishmaganday yana. | I12: 112
A13: 12 | B13: gp_pos_192 | C13: Google Play | D13: ijobiy | E13: Hali buni ustida ancha iwlaw kerak bunday olganda uzbekistondagi eng ishonarlisi shu | F13: buni ustida | G13: buning ustiga | H13: voqe bo‘lgani yetishmaganday yana. | I13: 112
... A139: 138 | B139: gp_neg_65 | C139: Google Play | D139: salbiy | E139: bunga odomlar mukkasidan ketishi va natijada bir nechta salbiy oqibatlar yuzaga kelishi mumkin | F139: mukkasidan ketishi | G139: mukka(si)dan ketmoq | H139: o‘zini tiya olmaslik darajada berilib ketmoq (salbiy). | I139: 318
A140: 139 | B140: gp_neg_65 | C140: Google Play | D140: salbiy | E140: bunga odomlar mukkasidan ketishi va natijada bir nechta salbiy oqibatlar yuzaga kelishi mumkin | F140: yuzaga kelishi | G140: yuzaga kelmoq | I140: 577
A141: 140 | B141: gp_neg_66 | C141: Google Play | D141: salbiy | E141: telefonda xotira kam bo'lganda telfonning ÃÀËÅÐÅßsiga kirmaydi | F141: kam bo'lganda | G141: kam bo‘lmaslik | H141: hech narsa yutqizmaslik, ozmi-ko‘pmi yutuqqa ega bo‘lmoq. | I141: 236
A142: 141 | B142: gp_neg_67 | C142: Google Play | D142: salbiy | E142: bu lug'atga ko'p so'zlar kiritilmagan | F142: so'zlar kiritilmagan | G142: so‘zga kirmoq kim? (varianti: gap(i)ga kirmoq) | H142: aytganini qilmoq. | I142: 173
A143: 142 | B143: gp_neg_94 | C143: Google Play | D143: salbiy | E143: Ilova dizayn jihatdan juda oddiy va did jihatdan yaxshi ko'rinishga ega emas; | F143: yaxshi ko'rinishga | G143: yaxshi ko‘rmoq | H143: 1) kim? kimni? sevmoq, oshiq-ma’shuq bo‘lmoq (qiz bilan yigit, er bilan xotin). 2) kim? kimni? sevmoq, izzat-hurmat qilmoq (ona bolani, aka ukani). 3) kim? nimani? ba’zan nima? kimni? yoqtirmoq. | I143: 546
A144: 143 | B144: gp_neg_96 | C144: Google Play | D144: salbiy | E144: Ilova bilan ishlash jarayonida ma'lumot almashish jarayoni tezroq amalga oshmasligi; | F144: amalga oshmasligi | G144: amalga oshmoq | I144: 39
A145: 144 | B145: gp_neg_102 | C145: Google Play | D145: salbiy | E145: O'yin daturlariga kirish jarayoni tez amalga oshmasligi; | F145: amalga oshmasligi | G145: amalga oshmoq | I145: 39
A146: 145 | B146: gp_neg_106 | C146: Google Play | D146: salbiy | E146: Yangilanish jarayonining ko'p vaqt davomida amalga oshishi va hisobdan ko'proq mb yechib olishi; | F146: amalga oshishi | G146: amalga oshmoq | I146: 39
A147: 146 | B147: gp_neg_107 | C147: Google Play | D147: salbiy | E147: Tarjimon ilovalarda tezkor qidirish davomida kamchiliklar bo'lishi; | F147: kamchiliklar bo'lishi | G147: kam bo‘lmaslik | H147: hech narsa yutqizmaslik, ozmi-ko‘pmi yutuqqa ega bo‘lmoq. | I147: 236
A148: 147 | B148: gp_neg_108 | C148: Google Play | D148: salbiy | E148: O'yin ilovalarida bolalar psixologiyasiga salbiy ta'sir ko'rsatadi; | F148: tasir ko'rsatadi | G148: ta’sir ko‘rsatmoq | H148: ta’sir qilishga urinmoq. | I148: 482
A149: 148 | B149: gp_neg_113 | C149: Google Play | D149: salbiy | E149: Shareit ma'lumot uzatishga qulay,ammo undagi reklamalar va bildirishnomalar menga yoqmaydi.Ular meni asabimga tegadi | F149: asabimga tegadi | G149: asab(i)ga tegmoq | H149: asabini qo‘zg‘atmoq, g‘ijintirmoq. | I149: 47
A150: 149 | B150: gp_neg_125 | C150: Google Play | D150: salbiy | E150: Musixmatch ilovasining interfeysi yaxshi tuzilmagan.ko'zga ko'rimsiz. | F150: ko'zga ko'rimsiz | G150: ko‘z(i) ko‘rdi | H150: nima[ning]? kimni? yoki nimani? yomon niyatini amalga oshirish uchun obyekt qilib tanlamoq. | I150: 259
A151: 150 | B151: gp_neg_176 | C151: Google Play | D151: salbiy | E151: ko'p ilovalar yuklanganda qurilma ishdan chiqadi | F151: ishdan chiqadi | G151: ish chiqmadi | H151: nima qilishdan? nimadan? yoki kimdan? | I151: 206
A152: 151 | B152: gp_neg_177 | C152: Google Play | D152: salbiy | E152: Sistema ishga tushmaydi | F152: ishga tushmaydi | G152: ish(i) tushdi | H152: biror ish yuzasidan muomalada bo‘lmoq, biror masala yuzasidan murojaat qilmoq. | I152: 206
A153: 152 | B153: gp_neg_179 | C153: Google Play | D153: salbiy | E153: dastur qurulmaga togri kelmaydi | F153: togri kelmaydi | G153: to‘g‘ri kelgan | H153: daf’atan nima yoki kim uchrasa shu. | I153: 519
A154: 153 | B154: gp_neg_185 | C154: Google Play | D154: salbiy | E154: ilovaga kelgan rasmalarni gahida acadi gahida esa ozidan ozi yoq bolup kaladi | F154: ozi yoq | G154: o‘z(i)da yo‘q | H154: benihoyat, juda-juda («xursand»). | I154: 610
A155: 154 | B155: gp_neg_189 | C155: Google Play | D155: salbiy | E155: ilova talabga javob bermaydi | F155: javob bermaydi | G155: javob bermoq | H155: 1) kim? yoki nima? nimaga? yoki kimga? javob qilmoq. 2) kim? nimaga? nima bilan? javoban ish tutmoq. 3) nima? nimaga? qondirmoq. 4) kim? nimaga? javobgarlikni o‘z ustiga olmoq. 5) kim? kimga?… | I155: 215
A156: 155 | B156: gp_neg_195 | C156: Google Play | D156: salbiy | E156: dasturni ishga tushirganda o'z vazifalarini bajarmay umumman boshqa vazifalarni bajaradi | F156: ishga tushirganda | G156: ish(i) tushdi ishga tushirmoq kim? nimani? (varianti: ishga tushmoq) | H156: biror ish yuzasidan muomalada bo‘lmoq, biror masala yuzasidan murojaat qilmoq. 1) kim? mehnat qilishni boshlamoq. 2) nima? ishlay boshlamoq. 3) kim? nimani? | I156: 206 || 207
A157: 156 | B157: gp_neg_197 | C157: Google Play | D157: salbiy | E157: ilova ko'p vaqtda ishga tushadi | F157: ishga tushadi | G157: ish(i) tushdi | H157: biror ish yuzasidan muomalada bo‘lmoq, biror masala yuzasidan murojaat qilmoq. | I157: 206
A158: 157 | B158: gp_neg_207 | C158: Google Play | D158: salbiy | E158: ilovani ishlatganda qurilmadagi ba'zi funksiyalar ishdan chiqadi | F158: ishdan chiqadi | G158: ish chiqmadi | H158: nima qilishdan? nimadan? yoki kimdan? | I158: 206
... A167: 166 | B167: gp_neg_295 | C167: Google Play | D167: salbiy | E167: dastur ishga tushishi juda qiyin | F167: ishga tushishi | G167: ish(i) tushdi | H167: biror ish yuzasidan muomalada bo‘lmoq, biror masala yuzasidan murojaat qilmoq. | I167: 206
A168: 167 | B168: gp_neg_303 | C168: Google Play | D168: salbiy | E168: foydalanuvchilarni ko`pligidan tarmoqda nosozliklar yuzaga keladi | F168: yuzaga keladi | G168: yuzaga kelmoq | I168: 577
A169: 168 | B169: gp_neg_305 | C169: Google Play | D169: salbiy | E169: aksariyat foydalanuvchilarni bemalol server kompyuteridan osonlik bilan foydalanishiga yo`l qo`yilishi | F169: yo'l qo'yilishi | G169: yo‘l qo‘ymoq | H169: voqe bo‘lishiga imkon bermoq. | I169: 584
A170: 169 | B170: gp_neg_315 | C170: Google Play | D170: salbiy | E170: yuklash paytida juda ko`p sahifalar ochishga to`gri keladiso`rovnomalar ketma-ketligi odamni jahlini chiqaradi | F170: to'gri keladiso'rovnomalar | G170: to‘g‘ri kelgan | H170: daf’atan nima yoki kim uchrasa shu. | I170: 519
A171: 170 | B171: gp_neg_315 | C171: Google Play | D171: salbiy | E171: yuklash paytida juda ko`p sahifalar ochishga to`gri keladiso`rovnomalar ketma-ketligi odamni jahlini chiqaradi | F171: jahlini chiqaradi | G171: jahl(i) chiqdi jahl(i)ni chiqarmoq | H171: g‘azablanmoq. | I171: 214
A172: 171 | B172: gp_neg_323 | C172: Google Play | D172: salbiy | E172: quvvat isrofi haddan ziyod | F172: haddan ziyod | G172: haddan ziyod | H172: ortiq darajada, nihoyatda (eskirgan). | I172: 181
A173: 172 | B173: gp_neg_331 | C173: Google Play | D173: salbiy | E173: Talabga javob bermaydi. | F173: javob bermaydi | G173: javob bermoq | H173: 1) kim? yoki nima? nimaga? yoki kimga? javob qilmoq. 2) kim? nimaga? nima bilan? javoban ish tutmoq. 3) nima? nimaga? qondirmoq. 4) kim? nimaga? javobgarlikni o‘z ustiga olmoq. 5) kim? kimga?… | I173: 215
...

Sheet Ko'chma so'zlar
A1: № | B1: Izoh ID | C1: Manba | D1: Sentiment | E1: Izoh matni | F1: Topilgan parcha | G1: Leksikon birligi | H1: Lug'aviy izoh (ma'nosi) | I1: Uslub belgisi | J1: Tekshiruv (ha / yo'q / shubhali) | K1: Annotator izohi
A2: 1 | B2: gp_pos_3 | C2: Google Play | D2: ijobiy | E2: Barakalla! Yaxshi tashkil etilgan va ko'rsatma berildi. Yangi yilingiz bilan! | F2: etilgan | G2: etilmoq | H2: 4) Pishib etmoq, dolzarb boʻlmoq. 5) s.t. Kayfi oshmoq; qattiq mast boʻlmoq. Har kim bilan qadah urishtirib ichaverib, rosa etilibdi.
A3: 2 | B3: gp_pos_5 | C3: Google Play | D3: ijobiy | E3: Juda zo'r Ovqat jonu dilim | F3: dilim | G3: dil | H3: 2) Kishining ichki ruhiy dunyosi, ichki his-tuygʻularining markazi, ramzi; koʻngil, qalb. Muhabbat — dil mevasi. Maqol. Dilda boʻlsa, tilga keladi.… 3) Koʻngildagi narsa (tilak, maqsad, niyat, oʻy, fikr va sh. k.). Dili toʻgʻrining yoʻli toʻgʻri. Maqol. Qoʻli qingʻirning dili qingʻir. Maqol. Choʻpon… 4) Kishining xotiri, es, yod, xayol; koʻngil.
A4: 3 | B4: gp_pos_6 | C4: Google Play | D4: ijobiy | E4: Juda foydali dastur. Rahmat | F4: foydali | G4: foydali | H4: 2) Maʼnaviy jihatdan biror manfaati, nafi tegadigan.
A5: 4 | B5: gp_pos_7 | C5: Google Play | D5: ijobiy | E5: Judayam ajoyib dastur ekan! Turmush o'rtog'imga ham juda yoqdi, endi judayam mazali taomlar retseptini qulaygina o'rganib olish mumkin. Dastur mualliflariga tashakkur! OMAD! | F5: retseptini | G5: retsept | H5: 3) s.t. Ogʻir, noqulay holatlardagi harakatlar uchun tayyor yoʻl-yoʻriq, qolip, andaza. Har xil vaziyatga yaraydigan, hammabop axloqiy-estetik qoidalar…
A6: 5 | B6: gp_pos_10 | C6: Google Play | D6: ijobiy | E6: Yoqdi Juda yaxshi app bo'lgan Ayniqsa chet elliklarga ko'rsatishga juda qulay. Developerlarga Omads! | F6: chet | G6: chet | H6: 4) Begona, ajnabiy, xorijiy.
A7: 6 | B7: gp_pos_13 | C7: Google Play | D7: ijobiy | E7: Rahmat Yashang besh baho! | F7: baho | G7: baho | H7: 2) Ahamiyat, mohiyat, qadr-qimmat. Bizda suvning bahosi oltinga teng. Baho bermoq 1) bahosini, narxini beltilamoq; 2) biror kimsa, narsa yoki…
A8: 7 | B8: gp_pos_18 | C8: Google Play | D8: ijobiy | E8: Good Job! Master akaning ushbu ilova-dasturi mengayam juda yoqdi. O'zim biz nechtasiga tavsiya qildim. Aytgancha, ushbu dasturchining Al-Qalam degan ilova-dasturi ham zo'r chiqqan. | F8: qalam | G8: qalam | H8: 4) Yozma asar ijod etish; yozma ijod, ijod.
A9: 8 | B9: gp_pos_20 | C9: Google Play | D9: ijobiy | E9: Salom! Assalomu alaykum barchaga! Buni judayam foydali appligiga xech qanday shubxa yo`q! Mansur aka qachon uylandiz oka? Shu appdan foydalangan xolga mazali taomlardan baxramand bo`lib baxtli va uzoq umr kechiringlar! | F9: foydali | G9: foydali | H9: 2) Maʼnaviy jihatdan biror manfaati, nafi tegadigan.
A10: 9 | B10: gp_pos_20 | C10: Google Play | D10: ijobiy | E10: Salom! Assalomu alaykum barchaga! Buni judayam foydali appligiga xech qanday shubxa yo`q! Mansur aka qachon uylandiz oka? Shu appdan foydalangan xolga mazali taomlardan baxramand bo`lib baxtli va uzoq umr kechiringlar! | F10: uzoq | G10: uzoq | H10: 4) Bevosita aloqasi, munosabati yoʻq,; aloqasiz.
A11: 10 | B11: gp_pos_21 | C11: Google Play | D11: ijobiy | E11: Raxmat Juda Zo'r dastur ekan! Kak raz shunaqangi dasturlar kerak edi biz yoshlarga! Jamoadan kelajakda bundanam yaxshilarini kutib qolamiz | F11: yoshlarga | G11: yosh | H11: 5) Etarli tajribaga ega boʻlmagan, tajribasiz.
A12: 11 | B12: gp_pos_21 | C12: Google Play | D12: ijobiy | E12: Raxmat Juda Zo'r dastur ekan! Kak raz shunaqangi dasturlar kerak edi biz yoshlarga! Jamoadan kelajakda bundanam yaxshilarini kutib qolamiz | F12: kutib | G12: kutmoq | H12: 6) Yoʻlida, hayot yoʻlida roʻpara boʻlmoq, istiqbolida boʻlmoq; qarshilamoq. Darhaqiqat, bizning qarshimizga yoʻlbars chiqsa, biz qattiq qoʻrqamiz,…
A13: 12 | B13: gp_pos_23 | C13: Google Play | D13: ijobiy | E13: Ajoyib Rasmlari bn juda yahshi tushunarli yozilgan rahmat! Iltimos taomnomani kupaytirsangiz ayniqsa shirinliklar qushilsa yanada yahshi bulardi. | F13: shirinliklar | G13: shirin shirinlik | H13: 3) Kishi huzur qiladigan, orom oladigan, lazzatlanadigan, xush yoqadigan; yoqimli, yoqimtoy. Shirin xayollar. Shirin tush koʻrmoq. Shirin muomala.… 3) Shodu xurramlik, vaqtichogʻlik, xursandlik; yaxshilik.
... A16: 15 | B16: gp_pos_27 | C16: Google Play | D16: ijobiy | E16: Gap yo'q Chetda yurgan studentlaga zo'r application, rahmat! )) | F16: chetda | G16: chet | H16: 4) Begona, ajnabiy, xorijiy.
A17: 16 | B17: gp_pos_31 | C17: Google Play | D17: ijobiy | E17: Uy bekalari uchun eng zo'r sovg'a ekan. Ayolimga juda yoqdi! | F17: bekalari | G17: beka | H17: 2) Oilaga, xonadonga yoki xoʻjalikka boshchilik qiluvchi ayol. Bogʻbonsiz bogʻ misli choʻl-yobon, Bekasiz uy — suvsiz tegirmon. eQanotli soʻzlaro. 3) Boshqaruvchi, sardor, ega, sohib. | I17: poet.
A18: 17 | B18: gp_pos_32 | C18: Google Play | D18: ijobiy | E18: Yaxshi va har kuni hammaga asqotishi mumkin boo'lgan sahifa! | F18: sahifa | G18: sahifa | H18: 4) Davomli butun bir hodisa, hayot va sh. k. ning ayrim davri.
A19: 18 | B19: gp_pos_33 | C19: Google Play | D19: ijobiy | E19: Zo'r! Katta raxmat shu app ni yaratganilar uchun! | F19: katta | G19: katta | H19: 7) Koʻzga koʻringan; atoqli, mashhur.
A20: 19 | B20: gp_pos_35 | C20: Google Play | D20: ijobiy | E20: Judayam foydali dastur !! | F20: foydali | G20: foydali | H20: 2) Maʼnaviy jihatdan biror manfaati, nafi tegadigan.
A21: 20 | B21: gp_pos_53 | C21: Google Play | D21: ijobiy | E21: Katta rahmat | F21: katta | G21: katta | H21: 7) Koʻzga koʻringan; atoqli, mashhur.
A22: 21 | B22: gp_pos_58 | C22: Google Play | D22: ijobiy | E22: 5-yulduz !!! Ajoyib ilova !!! Yaxshi ish!!! | F22: yulduz | G22: yulduz | H22: 3) Mashhur boʻlib tanilgan, shuhrat qozongan shaxs haqida.
A23: 22 | B23: gp_pos_88 | C23: Google Play | D23: ijobiy | E23: Tashakkur Assalomalekum. dasturga umuman gap yuq. Uzimni hamma narsaga qodir odamdek his qildim. Bularkanku. Qoyilman. Hamma ijodkorlariga katta rahmat. | F23: katta | G23: katta | H23: 7) Koʻzga koʻringan; atoqli, mashhur.
A24: 23 | B24: gp_pos_89 | C24: Google Play | D24: ijobiy | E24: Foydali | F24: foydali | G24: foydali | H24: 2) Maʼnaviy jihatdan biror manfaati, nafi tegadigan.
A25: 24 | B25: gp_pos_101 | C25: Google Play | D25: ijobiy | E25: Juda foydali! Ayniqsa, siz istagan paytda USSD-menyu orqali ishlamasligingiz kerak. | F25: foydali | G25: foydali | H25: 2) Maʼnaviy jihatdan biror manfaati, nafi tegadigan.
A26: 25 | B26: gp_pos_101 | C26: Google Play | D26: ijobiy | E26: Juda foydali! Ayniqsa, siz istagan paytda USSD-menyu orqali ishlamasligingiz kerak. | F26: orqali | G26: orqa | H26: 6) Homiy, suyanchiq, tirak. Togʻdan orqasi boʻlganning toshdan yuragi boʻlar. Maqol. Orqa qilmoq Biror shaxs yordamiga, himoyasiga, kuchiga ishonmoq,…
A27: 26 | B27: gp_pos_105 | C27: Google Play | D27: ijobiy | E27: Savol Nimaga menda internet orqali ishlamayapti? So'rovlarni USSD orqali yuboryapti. Podtverjdeniya uchun qanaqadir kod sÃ¶rayapti sms orqali kelgan. Menga hech qanday kod kelmadi. Nima qilishim kerak? | F27: orqali | G27: orqa | H27: 6) Homiy, suyanchiq, tirak. Togʻdan orqasi boʻlganning toshdan yuragi boʻlar. Maqol. Orqa qilmoq Biror shaxs yordamiga, himoyasiga, kuchiga ishonmoq,…
A28: 27 | B28: gp_pos_108 | C28: Google Play | D28: ijobiy | E28: Very good app Gap yo'q usd sorov turli noquleyliklar tugdirardi endi bu ancha osonlashtirdi | F28: tugdirardi | G28: tugmoq | H28: 4) Yigmoq, toʻplab gʻamlamoq. Topganini tugadi.
A29: 28 | B29: gp_pos_109 | C29: Google Play | D29: ijobiy | E29: Uzbek tilini qowiw Kerek qolganiga gap yo | F29: tilini | G29: til | H29: 6) Insondan boshqa narsalarning oʻzaro bir-birini tushunishga xizmat qiladigan vositasi, ifoda vositasi (belgisi). Qush tilini qush biladi. Maqol.
... A45: 44 | B45: gp_pos_187 | C45: Google Play | D45: ijobiy | E45: Eng foydali va eng yaxshi dasturni sotish va sotib olish. | F45: foydali | G45: foydali | H45: 2) Maʼnaviy jihatdan biror manfaati, nafi tegadigan.
A46: 45 | B46: gp_pos_187 | C46: Google Play | D46: ijobiy | E46: Eng foydali va eng yaxshi dasturni sotish va sotib olish. | F46: sotib | G46: sotmoq | H46: 2) Sotqinlik, xoinlik qilmoq. | I46: nafr.
A47: 46 | B47: gp_pos_215 | C47: Google Play | D47: ijobiy | E47: Juda foydali va kerakli application | F47: foydali | G47: foydali | H47: 2) Maʼnaviy jihatdan biror manfaati, nafi tegadigan.
A48: 47 | B48: gp_pos_217 | C48: Google Play | D48: ijobiy | E48: Buladi | F48: buladi | G48: bulamoq | H48: 2) Boʻlar-boʻlmas ayblar bilan qoralamoq, asossiz ayblamoq; fosh qilmoq.
A49: 48 | B49: gp_pos_227 | C49: Google Play | D49: ijobiy | E49: Faqat ikkinchi narsalar haqida ma'lumot olish foydali | F49: foydali | G49: foydali | H49: 2) Maʼnaviy jihatdan biror manfaati, nafi tegadigan.
A50: 49 | B50: gp_pos_242 | C50: Google Play | D50: ijobiy | E50: Yaxshi zo'r Shu Narxlarni O'zimizni Sum da Quyilsa juda yaxshi tushinardik | F50: quyilsa | G50: quyilmoq | H50: 2) Juda koʻp, kuchli tarzda (oqim tarzida) kelmoq,; yogʻilmoq.
A51: 50 | B51: gp_pos_244 | C51: Google Play | D51: ijobiy | E51: Albatta foydalidir | F51: foydalidir | G51: foydali | H51: 2) Maʼnaviy jihatdan biror manfaati, nafi tegadigan.
A52: 51 | B52: gp_pos_245 | C52: Google Play | D52: ijobiy | E52: Yaxshi ishlaydi, Force yaqin muammosi aniqlandi. Rahmat. | F52: yaqin | G52: yaqin | H52: 4) Doʻstona munosabatda boʻlgan, qadrdon, mehribon.
A53: 52 | B53: gp_pos_255 | C53: Google Play | D53: ijobiy | E53: Yaxshi prog. Juda ham foydali app onlayn bozo'r gap yuq. | F53: foydali | G53: foydali | H53: 2) Maʼnaviy jihatdan biror manfaati, nafi tegadigan.
A54: 53 | B54: gp_pos_266 | C54: Google Play | D54: ijobiy | E54: O'zbek dasturlarini ichida eng zo'ri va eng keng tarqalgan dastur deb hisoblayman, xullas dasturga gap yo'q ayniqsa yangi qo'shipgan filtr xizmati juda zo'r chiqarildi, yuklab olgan megabaytlarga aslo achinmaydi kishi! | F54: tarqalgan | G54: tarqalmoq | H54: 6) Arimoq, arib yoʻq boʻlmoq; yoʻqolmoq, ketmoq.
A55: 54 | B55: gp_pos_267 | C55: Google Play | D55: ijobiy | E55: bu dastur o'z narsalarini sotishingiz va narsalarni sotib olishingiz mumkin | F55: sotib | G55: sotmoq | H55: 2) Sotqinlik, xoinlik qilmoq. | I55: nafr.
A56: 55 | B56: gp_pos_267 | C56: Google Play | D56: ijobiy | E56: bu dastur o'z narsalarini sotishingiz va narsalarni sotib olishingiz mumkin | F56: olishingiz | G56: olishmoq | H56: 3) Biron-bir toʻsiqni engish, uni bartaraf etish maqsadida tinimsiz harakat qilmoq. 4) Bahslashmoq, haq-huquq talashmoq, tortishmoq; bir-birini engish uchun tirishmoq. Hakimboyvachchaning yaqin doʻstlaridan bir kishi..
A57: 56 | B57: gp_pos_268 | C57: Google Play | D57: ijobiy | E57: yanayam takomillashtirsa bundan ham foydali bo'ladi hudo hohlasa | F57: foydali | G57: foydali | H57: 2) Maʼnaviy jihatdan biror manfaati, nafi tegadigan.
...

Sheet Barcha izohlar
A1: № | B1: Izoh ID | C1: Manba | D1: Sentiment | E1: Izoh matni | F1: Moslik bormi | G1: Dataset
A2: 1 | B2: gp_pos_1 | C2: Google Play | D2: ijobiy | E2: Super | F2: yo'q | G2: https://github.com/SanatbekMatlatipov/uzbek-sentiment-analysis
A3: 2 | B3: gp_pos_2 | C3: Google Play | D3: ijobiy | E3: Axa zo'r | F3: yo'q | G3: https://github.com/SanatbekMatlatipov/uzbek-sentiment-analysis
A4: 3 | B4: gp_pos_3 | C4: Google Play | D4: ijobiy | E4: Barakalla! Yaxshi tashkil etilgan va ko'rsatma berildi. Yangi yilingiz bilan! | F4: ha | G4: https://github.com/SanatbekMatlatipov/uzbek-sentiment-analysis
A5: 4 | B5: gp_pos_4 | C5: Google Play | D5: ijobiy | E5: Ajoyib application Gap bolishi mumkinmas. Juda ham zo'r | F5: ha | G5: https://github.com/SanatbekMatlatipov/uzbek-sentiment-analysis
A6: 5 | B6: gp_pos_5 | C6: Google Play | D6: ijobiy | E6: Juda zo'r Ovqat jonu dilim | F6: ha | G6: https://github.com/SanatbekMatlatipov/uzbek-sentiment-analysis
A7: 6 | B7: gp_pos_6 | C7: Google Play | D7: ijobiy | E7: Juda foydali dastur. Rahmat | F7: ha | G7: https://github.com/SanatbekMatlatipov/uzbek-sentiment-analysis
A8: 7 | B8: gp_pos_7 | C8: Google Play | D8: ijobiy | E8: Judayam ajoyib dastur ekan! Turmush o'rtog'imga ham juda yoqdi, endi judayam mazali taomlar retseptini qulaygina o'rganib olish mumkin. Dastur mualliflariga tashakkur! OMAD! | F8: ha | G8: https://github.com/SanatbekMatlatipov/uzbek-sentiment-analysis
A9: 8 | B9: gp_pos_8 | C9: Google Play | D9: ijobiy | E9: Ajoyib Alloh rozi bo'lsin, juda hayrli ish qilibsizlar. Aynan shunday app kerek edi... | F9: yo'q | G9: https://github.com/SanatbekMatlatipov/uzbek-sentiment-analysis
A10: 9 | B10: gp_pos_9 | C10: Google Play | D10: ijobiy | E10: OZBEK TAOMLARI DUNYODA ENG zo'r! Ushbu dastur bizning ozbek taomlarini dunyoga tanitadi degan umiddaman. Mualiflarga rahmat! | F10: yo'q | G10: https://github.com/SanatbekMatlatipov/uzbek-sentiment-analysis
A11: 10 | B11: gp_pos_10 | C11: Google Play | D11: ijobiy | E11: Yoqdi Juda yaxshi app bo'lgan Ayniqsa chet elliklarga ko'rsatishga juda qulay. Developerlarga Omads! | F11: ha | G11: https://github.com/SanatbekMatlatipov/uzbek-sentiment-analysis
A12: 11 | B12: gp_pos_11 | C12: Google Play | D12: ijobiy | E12: E qoyil gap yo'q zo'r chiqibti | F12: yo'q | G12: https://github.com/SanatbekMatlatipov/uzbek-sentiment-analysis
A13: 12 | B13: gp_pos_12 | C13: Google Play | D13: ijobiy | E13: Gap yo'q oma qoil eng zo'r dastur | F13: yo'q | G13: https://github.com/SanatbekMatlatipov/uzbek-sentiment-analysis
... A5371: 5370 | B5371: rest_2610#8 | C5371: Restoran | D5371: salbiy | E5371: Bu katta kamchilik. | F5371: ha | G5371: https://github.com/SanatbekMatlatipov/UzABSA
